<?xml version="1.0"?>
<robot xmlns:xacro="http://www.ros.org/wiki/xacro">
    <xacro:macro name="striker" params="robot_name hardware_interface">
        <joint name="${robot_name}_striker" type="fixed">
            <parent link="${robot_name}_link_ee"/>
            <child link="${robot_name}_striker_base"/>
            <origin xyz="0.0 0.0 0.0" rpy="0 0 0"/>
        </joint>

        <link name="${robot_name}_striker_base">
            <inertial>
                <origin xyz="0 0 0.156" rpy="0 0 0"/>
                <mass value="0.350"/>
<!--                <inertia ixx="0.000297" ixy="0.0" ixz="0.0"-->
<!--                         iyy="0.000271" iyz="0.0" izz="0.0000653"/>-->
                <inertia ixx="0.005" ixy="0.0" ixz="0.0"
                         iyy="0.005" iyz="0.0" izz="0.001"/>
            </inertial>
            <visual>
                <origin xyz="0 0 0" rpy="0 0.0 0"/>
                <geometry>
                    <mesh filename="package://air_hockey_description/meshes/striker/visual/EE_arm.stl"/>
                </geometry>
                <material name="LightGrey"/>
            </visual>
            <collision>
                <origin xyz="0 0 0" rpy="0 0 0"/>
                <geometry>
                    <mesh filename="package://air_hockey_description/meshes/striker/collision/EE_arm_collision.stl"/>
                </geometry>
            </collision>
        </link>

        <joint name="${robot_name}_striker_joint_1" type="revolute">
            <parent link="${robot_name}_striker_base"/>
            <child link="${robot_name}_striker_joint_link"/>
            <origin xyz="0.0 0.0 0.515" rpy="0 0 0"/>
            <axis xyz="0 1 0"/>
            <limit effort="10" lower="-${PI/2}" upper="${PI/2}" velocity="3.1415926"/>
            <safety_controller k_position="100" k_velocity="2" soft_lower_limit="-2.094395102"
                               soft_upper_limit="2.094395102"/>
            <dynamics damping="0.01"/>
        </joint>

        <link name="${robot_name}_striker_joint_link">
            <inertial>
                <origin xyz="0 0.0 0" rpy="0 0 0"/>
                <mass value="0.1"/>vvvvv
                <inertia ixx="0.001" ixy="0.0" ixz="0.0"
                         iyy="0.001" iyz="0.0" izz="0.001"/>
            </inertial>
        </link>

        <joint name="${robot_name}_striker_joint_2" type="revolute">
            <parent link="${robot_name}_striker_joint_link"/>
            <child link="${robot_name}_striker_mallet"/>
            <origin xyz="0.0 0.0 0.0" rpy="0 0 0"/>
            <axis xyz="1 0 0"/>
            <limit effort="10" lower="-${PI/2}" upper="${PI/2}" velocity="3.1415926"/>
            <safety_controller k_position="100" k_velocity="2" soft_lower_limit="-2.094395102"
                               soft_upper_limit="2.094395102"/>
            <dynamics damping="0.01"/>
        </joint>

        <link name="${robot_name}_striker_mallet">
            <inertial>
                <origin xyz="0 0.0 0.078" rpy="0 0 0"/>
                <mass value="0.183"/>
                <inertia
                        ixx="0.0001" ixy="0.0" ixz="0.0"
                        iyy="0.0001" iyz="0.0" izz="0.0001"/>
            </inertial>
            <visual>
                <origin xyz="0 0.0 0.0" rpy="0.0 0.0 0"/>
                <geometry>
                    <mesh filename="package://air_hockey_description/meshes/striker/visual/EE_mallet.stl"/>
                </geometry>
                <material name="LightGrey"/>
            </visual>
            <collision>
                <origin xyz="0 0.0 0.0" rpy="0.0 0.0 0"/>
                <geometry>
                    <mesh filename="package://air_hockey_description/meshes/striker/collision/EE_mallet_collision.stl"/>
                </geometry>
            </collision>
        </link>

        <joint name="${robot_name}_striker_mallet_fix" type="fixed">
            <parent link="${robot_name}_striker_mallet"/>
            <child link="${robot_name}_striker_mallet_tip"/>
            <origin xyz="0.0 0.0 0.095" rpy="0 0 0"/>
            <axis xyz="1 0 0"/>
        </joint>
        <!--  The striker frame is here defined -->
        <link name="${robot_name}_striker_mallet_tip">
            <inertial>
                <origin rpy="0 0 0" xyz="0 0 0.0"/>
                <mass value="0.1"/>
                <inertia ixx="0.0001" ixy="0.0" ixz="0.0"
                         iyy="0.0001" iyz="0.0" izz="0.0001"/>
            </inertial>
        </link>

        <gazebo reference="${robot_name}_striker_base">
            <material>Gazebo/Grey</material>
            <mu1>0.2</mu1>
            <mu2>0.2</mu2>
            <selfCollide>0</selfCollide>
        </gazebo>

        <gazebo reference="${robot_name}_striker_joint_link">
            <material>Gazebo/Grey</material>
            <mu1>0.2</mu1>
            <mu2>0.2</mu2>
            <selfCollide>0</selfCollide>
        </gazebo>

        <gazebo reference="${robot_name}_striker_mallet">
            <collision>
                <surface>
                    <bounce>
                        <restitution_coefficient>1.0</restitution_coefficient>
                        <threshold>0.0</threshold>
                    </bounce>
                    <contact>
                        <ode>
                            <kp>1e9</kp>
                            <max_vel>10</max_vel>
                        </ode>
                    </contact>
                </surface>
            </collision>
            <material>Gazebo/Grey</material>
            <mu1>1.0</mu1>
            <mu2>1.0</mu2>
            <selfCollide>0</selfCollide>
        </gazebo>

        <gazebo reference="${robot_name}_striker_mallet_fix">
            <preserveFixedJoint>1</preserveFixedJoint>
        </gazebo>

<!--        <transmission name="${robot_name}_striker_tran_1">-->
<!--            <robotNamespace>/${robot_name}</robotNamespace>-->
<!--            <type>transmission_interface/SimpleTransmission</type>-->
<!--            <joint name="${robot_name}_striker_joint_1">-->
<!--                <hardwareInterface>${hardware_interface}</hardwareInterface>-->
<!--            </joint>-->
<!--            <actuator name="${robot_name}_striker_motor_1">-->
<!--                <hardwareInterface>${hardware_interface}</hardwareInterface>-->
<!--                <mechanicalReduction>1</mechanicalReduction>-->
<!--            </actuator>-->
<!--        </transmission>-->

<!--        <transmission name="${robot_name}_striker_tran_2">-->
<!--            <robotNamespace>/${robot_name}</robotNamespace>-->
<!--            <type>transmission_interface/SimpleTransmission</type>-->
<!--            <joint name="${robot_name}_striker_joint_2">-->
<!--                <hardwareInterface>${hardware_interface}</hardwareInterface>-->
<!--            </joint>-->
<!--            <actuator name="${robot_name}_striker_motor_2">-->
<!--                <hardwareInterface>${hardware_interface}</hardwareInterface>-->
<!--                <mechanicalReduction>1</mechanicalReduction>-->
<!--            </actuator>-->
<!--        </transmission>-->

        <gazebo>
            <plugin name="univsersal_joint_plugin" filename="libuniversal_joint_plugin.so">
            </plugin>
        </gazebo>

    </xacro:macro>

</robot> 
